[2020-10-13 09:41:50,074: WARNING/MainProcess] consumer: Connection to broker lost. Trying to re-establish the connection...
Traceback (most recent call last):
  File "/home/tareq/Desktop/celery/venv/lib/python3.8/site-packages/celery/worker/consumer/consumer.py", line 311, in start
    blueprint.start(self)
  File "/home/tareq/Desktop/celery/venv/lib/python3.8/site-packages/celery/bootsteps.py", line 116, in start
    step.start(parent)
  File "/home/tareq/Desktop/celery/venv/lib/python3.8/site-packages/celery/worker/consumer/consumer.py", line 592, in start
    c.loop(*c.loop_args())
  File "/home/tareq/Desktop/celery/venv/lib/python3.8/site-packages/celery/worker/loops.py", line 81, in asynloop
    next(loop)
  File "/home/tareq/Desktop/celery/venv/lib/python3.8/site-packages/kombu/asynchronous/hub.py", line 361, in create_loop
    cb(*cbargs)
  File "/home/tareq/Desktop/celery/venv/lib/python3.8/site-packages/kombu/transport/base.py", line 235, in on_readable
    reader(loop)
  File "/home/tareq/Desktop/celery/venv/lib/python3.8/site-packages/kombu/transport/base.py", line 217, in _read
    drain_events(timeout=0)
  File "/home/tareq/Desktop/celery/venv/lib/python3.8/site-packages/amqp/connection.py", line 514, in drain_events
    while not self.blocking_read(timeout):
  File "/home/tareq/Desktop/celery/venv/lib/python3.8/site-packages/amqp/connection.py", line 520, in blocking_read
    return self.on_inbound_frame(frame)
  File "/home/tareq/Desktop/celery/venv/lib/python3.8/site-packages/amqp/method_framing.py", line 53, in on_frame
    callback(channel, method_sig, buf, None)
  File "/home/tareq/Desktop/celery/venv/lib/python3.8/site-packages/amqp/connection.py", line 526, in on_inbound_method
    return self.channels[channel_id].dispatch_method(
  File "/home/tareq/Desktop/celery/venv/lib/python3.8/site-packages/amqp/abstract_channel.py", line 143, in dispatch_method
    listener(*args)
  File "/home/tareq/Desktop/celery/venv/lib/python3.8/site-packages/amqp/connection.py", line 656, in _on_close
    raise error_for_code(reply_code, reply_text,
amqp.exceptions.ConnectionForced: (0, 0): (320) CONNECTION_FORCED - broker forced connection closure with reason 'shutdown'
[2020-10-13 09:41:50,074: WARNING/MainProcess] consumer: Connection to broker lost. Trying to re-establish the connection...
Traceback (most recent call last):
  File "/home/tareq/Desktop/celery/venv/lib/python3.8/site-packages/celery/worker/consumer/consumer.py", line 311, in start
    blueprint.start(self)
  File "/home/tareq/Desktop/celery/venv/lib/python3.8/site-packages/celery/bootsteps.py", line 116, in start
    step.start(parent)
  File "/home/tareq/Desktop/celery/venv/lib/python3.8/site-packages/celery/worker/consumer/consumer.py", line 592, in start
    c.loop(*c.loop_args())
  File "/home/tareq/Desktop/celery/venv/lib/python3.8/site-packages/celery/worker/loops.py", line 81, in asynloop
    next(loop)
  File "/home/tareq/Desktop/celery/venv/lib/python3.8/site-packages/kombu/asynchronous/hub.py", line 361, in create_loop
    cb(*cbargs)
  File "/home/tareq/Desktop/celery/venv/lib/python3.8/site-packages/kombu/transport/base.py", line 235, in on_readable
    reader(loop)
  File "/home/tareq/Desktop/celery/venv/lib/python3.8/site-packages/kombu/transport/base.py", line 217, in _read
    drain_events(timeout=0)
  File "/home/tareq/Desktop/celery/venv/lib/python3.8/site-packages/amqp/connection.py", line 514, in drain_events
    while not self.blocking_read(timeout):
  File "/home/tareq/Desktop/celery/venv/lib/python3.8/site-packages/amqp/connection.py", line 520, in blocking_read
    return self.on_inbound_frame(frame)
  File "/home/tareq/Desktop/celery/venv/lib/python3.8/site-packages/amqp/method_framing.py", line 53, in on_frame
    callback(channel, method_sig, buf, None)
  File "/home/tareq/Desktop/celery/venv/lib/python3.8/site-packages/amqp/connection.py", line 526, in on_inbound_method
    return self.channels[channel_id].dispatch_method(
  File "/home/tareq/Desktop/celery/venv/lib/python3.8/site-packages/amqp/abstract_channel.py", line 143, in dispatch_method
    listener(*args)
  File "/home/tareq/Desktop/celery/venv/lib/python3.8/site-packages/amqp/connection.py", line 655, in _on_close
    self._x_close_ok()
  File "/home/tareq/Desktop/celery/venv/lib/python3.8/site-packages/amqp/connection.py", line 670, in _x_close_ok
    self.send_method(spec.Connection.CloseOk, callback=self._on_close_ok)
  File "/home/tareq/Desktop/celery/venv/lib/python3.8/site-packages/amqp/abstract_channel.py", line 57, in send_method
    conn.frame_writer(1, self.channel_id, sig, args, content)
  File "/home/tareq/Desktop/celery/venv/lib/python3.8/site-packages/amqp/method_framing.py", line 183, in write_frame
    write(view[:offset])
  File "/home/tareq/Desktop/celery/venv/lib/python3.8/site-packages/amqp/transport.py", line 303, in write
    self._write(s)
ConnectionResetError: [Errno 104] Connection reset by peer
[2020-10-13 09:41:50,099: ERROR/MainProcess] consumer: Cannot connect to amqp://guest:**@127.0.0.1:5672//: [Errno 111] Connection refused.
Trying again in 2.00 seconds... (1/100)

[2020-10-13 09:41:50,112: ERROR/MainProcess] consumer: Cannot connect to amqp://guest:**@127.0.0.1:5672//: [Errno 111] Connection refused.
Trying again in 2.00 seconds... (1/100)

[2020-10-13 09:41:52,108: ERROR/MainProcess] consumer: Cannot connect to amqp://guest:**@127.0.0.1:5672//: [Errno 111] Connection refused.
Trying again in 4.00 seconds... (2/100)

[2020-10-13 09:41:52,122: ERROR/MainProcess] consumer: Cannot connect to amqp://guest:**@127.0.0.1:5672//: [Errno 111] Connection refused.
Trying again in 4.00 seconds... (2/100)

[2020-10-13 09:41:56,119: ERROR/MainProcess] consumer: Cannot connect to amqp://guest:**@127.0.0.1:5672//: [Errno 111] Connection refused.
Trying again in 6.00 seconds... (3/100)

[2020-10-13 09:41:56,141: ERROR/MainProcess] consumer: Cannot connect to amqp://guest:**@127.0.0.1:5672//: [Errno 111] Connection refused.
Trying again in 6.00 seconds... (3/100)

[2020-10-13 09:42:02,138: ERROR/MainProcess] consumer: Cannot connect to amqp://guest:**@127.0.0.1:5672//: [Errno 111] Connection refused.
Trying again in 8.00 seconds... (4/100)

[2020-10-13 09:42:02,154: ERROR/MainProcess] consumer: Cannot connect to amqp://guest:**@127.0.0.1:5672//: [Errno 111] Connection refused.
Trying again in 8.00 seconds... (4/100)

[2020-10-13 09:42:10,165: ERROR/MainProcess] consumer: Cannot connect to amqp://guest:**@127.0.0.1:5672//: [Errno 111] Connection refused.
Trying again in 10.00 seconds... (5/100)

[2020-10-13 09:42:10,179: ERROR/MainProcess] consumer: Cannot connect to amqp://guest:**@127.0.0.1:5672//: [Errno 111] Connection refused.
Trying again in 10.00 seconds... (5/100)

[2020-10-13 09:51:58,588: WARNING/MainProcess] consumer: Connection to broker lost. Trying to re-establish the connection...
Traceback (most recent call last):
  File "/home/tareq/Desktop/celery/venv/lib/python3.8/site-packages/celery/worker/consumer/consumer.py", line 311, in start
    blueprint.start(self)
  File "/home/tareq/Desktop/celery/venv/lib/python3.8/site-packages/celery/bootsteps.py", line 116, in start
    step.start(parent)
  File "/home/tareq/Desktop/celery/venv/lib/python3.8/site-packages/celery/worker/consumer/consumer.py", line 592, in start
    c.loop(*c.loop_args())
  File "/home/tareq/Desktop/celery/venv/lib/python3.8/site-packages/celery/worker/loops.py", line 81, in asynloop
    next(loop)
  File "/home/tareq/Desktop/celery/venv/lib/python3.8/site-packages/kombu/asynchronous/hub.py", line 361, in create_loop
    cb(*cbargs)
  File "/home/tareq/Desktop/celery/venv/lib/python3.8/site-packages/kombu/transport/base.py", line 235, in on_readable
    reader(loop)
  File "/home/tareq/Desktop/celery/venv/lib/python3.8/site-packages/kombu/transport/base.py", line 217, in _read
    drain_events(timeout=0)
  File "/home/tareq/Desktop/celery/venv/lib/python3.8/site-packages/amqp/connection.py", line 514, in drain_events
    while not self.blocking_read(timeout):
  File "/home/tareq/Desktop/celery/venv/lib/python3.8/site-packages/amqp/connection.py", line 520, in blocking_read
    return self.on_inbound_frame(frame)
  File "/home/tareq/Desktop/celery/venv/lib/python3.8/site-packages/amqp/method_framing.py", line 53, in on_frame
    callback(channel, method_sig, buf, None)
  File "/home/tareq/Desktop/celery/venv/lib/python3.8/site-packages/amqp/connection.py", line 526, in on_inbound_method
    return self.channels[channel_id].dispatch_method(
  File "/home/tareq/Desktop/celery/venv/lib/python3.8/site-packages/amqp/abstract_channel.py", line 143, in dispatch_method
    listener(*args)
  File "/home/tareq/Desktop/celery/venv/lib/python3.8/site-packages/amqp/connection.py", line 656, in _on_close
    raise error_for_code(reply_code, reply_text,
amqp.exceptions.ConnectionForced: (0, 0): (320) CONNECTION_FORCED - broker forced connection closure with reason 'shutdown'
[2020-10-13 09:51:58,604: WARNING/MainProcess] consumer: Connection to broker lost. Trying to re-establish the connection...
Traceback (most recent call last):
  File "/home/tareq/Desktop/celery/venv/lib/python3.8/site-packages/celery/worker/consumer/consumer.py", line 311, in start
    blueprint.start(self)
  File "/home/tareq/Desktop/celery/venv/lib/python3.8/site-packages/celery/bootsteps.py", line 116, in start
    step.start(parent)
  File "/home/tareq/Desktop/celery/venv/lib/python3.8/site-packages/celery/worker/consumer/consumer.py", line 592, in start
    c.loop(*c.loop_args())
  File "/home/tareq/Desktop/celery/venv/lib/python3.8/site-packages/celery/worker/loops.py", line 81, in asynloop
    next(loop)
  File "/home/tareq/Desktop/celery/venv/lib/python3.8/site-packages/kombu/asynchronous/hub.py", line 361, in create_loop
    cb(*cbargs)
  File "/home/tareq/Desktop/celery/venv/lib/python3.8/site-packages/kombu/transport/base.py", line 235, in on_readable
    reader(loop)
  File "/home/tareq/Desktop/celery/venv/lib/python3.8/site-packages/kombu/transport/base.py", line 217, in _read
    drain_events(timeout=0)
  File "/home/tareq/Desktop/celery/venv/lib/python3.8/site-packages/amqp/connection.py", line 514, in drain_events
    while not self.blocking_read(timeout):
  File "/home/tareq/Desktop/celery/venv/lib/python3.8/site-packages/amqp/connection.py", line 520, in blocking_read
    return self.on_inbound_frame(frame)
  File "/home/tareq/Desktop/celery/venv/lib/python3.8/site-packages/amqp/method_framing.py", line 53, in on_frame
    callback(channel, method_sig, buf, None)
  File "/home/tareq/Desktop/celery/venv/lib/python3.8/site-packages/amqp/connection.py", line 526, in on_inbound_method
    return self.channels[channel_id].dispatch_method(
  File "/home/tareq/Desktop/celery/venv/lib/python3.8/site-packages/amqp/abstract_channel.py", line 143, in dispatch_method
    listener(*args)
  File "/home/tareq/Desktop/celery/venv/lib/python3.8/site-packages/amqp/connection.py", line 655, in _on_close
    self._x_close_ok()
  File "/home/tareq/Desktop/celery/venv/lib/python3.8/site-packages/amqp/connection.py", line 670, in _x_close_ok
    self.send_method(spec.Connection.CloseOk, callback=self._on_close_ok)
  File "/home/tareq/Desktop/celery/venv/lib/python3.8/site-packages/amqp/abstract_channel.py", line 57, in send_method
    conn.frame_writer(1, self.channel_id, sig, args, content)
  File "/home/tareq/Desktop/celery/venv/lib/python3.8/site-packages/amqp/method_framing.py", line 183, in write_frame
    write(view[:offset])
  File "/home/tareq/Desktop/celery/venv/lib/python3.8/site-packages/amqp/transport.py", line 303, in write
    self._write(s)
ConnectionResetError: [Errno 104] Connection reset by peer
[2020-10-13 09:51:58,627: ERROR/MainProcess] consumer: Cannot connect to amqp://guest:**@127.0.0.1:5672//: [Errno 111] Connection refused.
Trying again in 2.00 seconds... (1/100)

[2020-10-13 09:51:58,639: ERROR/MainProcess] consumer: Cannot connect to amqp://guest:**@127.0.0.1:5672//: [Errno 111] Connection refused.
Trying again in 2.00 seconds... (1/100)

[2020-10-13 09:52:00,667: ERROR/MainProcess] consumer: Cannot connect to amqp://guest:**@127.0.0.1:5672//: [Errno 111] Connection refused.
Trying again in 4.00 seconds... (2/100)

[2020-10-13 09:52:00,667: ERROR/MainProcess] consumer: Cannot connect to amqp://guest:**@127.0.0.1:5672//: [Errno 111] Connection refused.
Trying again in 4.00 seconds... (2/100)

[2020-10-13 09:52:04,700: ERROR/MainProcess] consumer: Cannot connect to amqp://guest:**@127.0.0.1:5672//: [Errno 111] Connection refused.
Trying again in 6.00 seconds... (3/100)

[2020-10-13 09:52:04,709: ERROR/MainProcess] consumer: Cannot connect to amqp://guest:**@127.0.0.1:5672//: [Errno 111] Connection refused.
Trying again in 6.00 seconds... (3/100)

[2020-10-13 09:52:10,721: ERROR/MainProcess] consumer: Cannot connect to amqp://guest:**@127.0.0.1:5672//: [Errno 111] Connection refused.
Trying again in 8.00 seconds... (4/100)

[2020-10-13 09:52:10,742: ERROR/MainProcess] consumer: Cannot connect to amqp://guest:**@127.0.0.1:5672//: [Errno 111] Connection refused.
Trying again in 8.00 seconds... (4/100)

[2020-10-13 09:52:18,744: ERROR/MainProcess] consumer: Cannot connect to amqp://guest:**@127.0.0.1:5672//: [Errno 111] Connection refused.
Trying again in 10.00 seconds... (5/100)

[2020-10-13 09:52:18,769: ERROR/MainProcess] consumer: Cannot connect to amqp://guest:**@127.0.0.1:5672//: [Errno 111] Connection refused.
Trying again in 10.00 seconds... (5/100)

